Workbook

Sheet All Content (Mobs, Items)
A1: Dev? | B1: Hide? | C1: Type | D1: Name | E1: Priority | F1: Starter? | G1: Tier | H1: Count | I1: ATK | J1: HP | K1: Ability | L1: Updated by... | M1: (when updated) | N1: Updates... | O1: (when updates) | P1: Special Function | Q1: Defined | R1: Exceptions / Edge Cases
A2: TRUE | B2: FALSE | C2: M | D2: Wizard | E2: 1 | F2: Starter | G2: 1 | H2: 2 | I2: 5 | J2: 2 | K2: --- | L2: --- | N2: --- | O2: --- | P2: --- | Q2: --- | R2: ---
A3: TRUE | B3: FALSE | C3: M | D3: Golem | E3: 1 | F3: Starter | G3: 1 | H3: 2 | I3: 3 | J3: 7 | K3: --- | L3: --- | N3: --- | O3: --- | P3: --- | Q3: --- | R3: ---
A4: TRUE | B4: FALSE | C4: M | D4: Goblin | E4: 3 | F4: Starter | G4: 1 | H4: 2 | I4: 3 | J4: 1 | K4: Cannot receive ATK damage. | L4: --- | M4: --- | N4: --- | O4: --- | P4: (No ATK Dmg) | Q4: (No ATK Dmg): This unit's HP can never be reduced. Note that this unit can be defeated through all other means. | R4: ---
A5: TRUE | B5: FALSE | C5: M | D5: Skeleton | E5: 3 | F5: Starter | G5: 1 | H5: 2 | I5: 3 | J5: X (3) | K5: X = The HP of the last enemy faced. | L5: (HP of last enemy spun) | M5: >On Spin | N5: --- | O5: --- | P5: (Last Mob HP) | Q5: Last Mob HP: On Spin, immediately store the enemy's HP in this value. Overwrite this value each time On Spin occurs. | R5: Edge Case: If this is the first unit faced, set HP to 3.
A6: TRUE | B6: FALSE | C6: M | D6: Hornet Swarm | E6: 3 | F6: Starter | G6: 1 | H6: 2 | I6: 2 | J6: 3 | K6: This unit attacks twice. | L6: --- | M6: --- | N6: --- | O6: --- | P6: [Attacks Twice] | Q6: On Resolve Combat, takes its current ATK and deals dmg to the player two times.
A7: TRUE | B7: FALSE | C7: M | D7: Lich | E7: 4 | F7: Uncommon | G7: 1 | H7: 2 | I7: 3 | J7: 1 | K7: Adds 1 to the HP of neighboring Monsters. | L7: --- | M7: --- | N7: Neighboring HP | O7: >On Remove Slice | P7: --- | Q7: (Neighboring HP): This addition to HP will always take place after all other calculations and modifiers have been added. | R7: ---
A8: TRUE | B8: FALSE | C8: M | D8: Ogre | E8: 1 | F8: Starter | G8: 2 | H8: 2 | I8: 4 | J8: X | K8: X = Your HP at the start of combat. | L8: (HP) | M8: >On Spin | N8: --- | O8: --- | P8: --- | Q8: --- | R8: ---
A9: TRUE | B9: FALSE | C9: M | D9: Berserker | E9: 2 | F9: Starter | G9: 2 | H9: 1 | I9: (1+X) | J9: (2+X) | K9: X = The number of monsters you have defeated. | L9: (# Mob Defeated) | M9: >On Remove Slice | N9: --- | O9: --- | P9: (# Mobs Defeated) | Q9: (# Mobs Defeated): Every time a slice is removed after the initial drafting phase, this increments. | R9: ---
A10: TRUE | B10: FALSE | C10: M | D10: Dire Wolf | E10: 2 | F10: Starter | G10: 2 | H10: 2 | I10: X | J10: 3 | K10: X = Your HP at the start of combat. | L10: (HP) | M10: >On Spin | N10: --- | O10: --- | P10: --- | Q10: --- | R10: ---
A11: TRUE | B11: FALSE | C11: M | D11: Bandit | E11: 2 | F11: Uncommon | G11: 2 | H11: 2 | I11: X | J11: 3 | K11: X = The number of items you have at the start of combat. | L11: (# Items) | M11: >On Draft >On Spin | N11: --- | O11: --- | P11: --- | Q11: --- | R11: ---
A12: FALSE | B12: FALSE | C12: M | D12: Leech League | E12: 2 | F12: Uncommon | G12: 2 | H12: 1 | I12: 4 | J12: (1+X) | K12: X = The number of monsters still in play. | L12: (# mobs) | M12: >On Remove Slice | N12: --- | O12: --- | P12: --- | Q12: --- | R12: ---
A13: TRUE | B13: FALSE | C13: M | D13: Wraith | E13: 3 | F13: Uncommon | G13: 2 | H13: 2 | I13: 3 | J13: 3 | K13: If a neighbor has higher ATK, then this unit's ATK will match it. | L13: [Neighbors' highest ATK] | M13: >On Remove Slice | N13: Its own ATK | O13: >On Remove Slice | P13: --- | Q13: Resolve Order: This is the only function whose order of operations matters. Wraith will check the ATK of others (with their complete modifiers, if any) and "match" higher ATK if applicable, and then will receive the ATK increase from Captain. | R13: ---
A14: FALSE | B14: FALSE | C14: M | D14: Mimic | E14: 4 | F14: Uncommon | G14: 2 | H14: 1 | I14: 4 | J14: 5 | K14: If this unit is defeated before it can attack, Gain 1 random item. | L14: (Did it attack?) | M14: >On Resolve Combat | N14: Initiates [Gain 1 Item] If (Did it attack?) returns False | O14: >On Resolve Combat | P14: (Did it attack?) [Gain 1 Item] | Q14: (Did It Attack?): Set to False at the start of combat. If the enemy ever attacks, set to True. Ways to prevent the enemy from attacking are killing or otherwise defeating the enemy with items (i.e. not blocking). Draws 1 Random item (tier-agnostic) from the pool of items that have not been drawn in this dungeon yet. | R14: Edge Case: If there are 0 items left in the pool, then do not draw an item.
A15: FALSE | B15: FALSE | C15: M | D15: Two-Headed Serpent | E15: 4 | F15: Starter | G15: 2 | H15: 1 | I15: 5 | J15: 5 | K15: Does not attack if you use at least 2 items. | L15: (# items used this combat) | M15: >On Item Use | N15: --- | O15: --- | P15: [Used 2 Items?] | Q15: Checks if player uses (or 'taps') 2 items during its combat, at which point its ATK immediately drops to zero (0). | R15: Edge Case: If the second item used is Smoke Bomb, nothing special happens. Smoke Bomb occurs as usual, and (later) when the player encounters Two-Headed Serpent again, they will still be set to attack again.
A16: FALSE | B16: FALSE | C16: M | D16: Slime Boss | E16: 2 | F16: Starter | G16: 3 | H16: 1 | I16: X | J16: 9 | K16: X = This unit's HP. | L16: (Enemy HP) | M16: >On Enemy HP Change | N16: Its own ATK | O16: >On Enemy HP Change | R16: Edge Case: This is the only unit whose ATK value can change mid-combat. This means that dealing it damage can effect items that react to enemy ATK (Sai, Fangs, Sledgehammer).
A17: FALSE | B17: FALSE | C17: M | D17: Spider Queen | E17: 3 | F17: Uncommon | G17: 3 | H17: 1 | I17: 3 | J17: 7 | K17: When this unit attacks, if it has more HP than at least one neighbor it attacks twice. | L17: (Neighbor with less HP?) | M17: >On Enemy HP Change | N17: (# Times Attack) | O17: >On Resolve Combat | P17: (Neighbor with less HP?) | Q17: Each time On Enemy HP Change, checks all Neigbors to see if they have less HP than. If True, then sets (# Times Attack) to 2. | R17: ---
A18: TRUE | B18: FALSE | C18: M | D18: Commander | E18: 4 | F18: Uncommon | G18: 3 | H18: 2 | I18: 3 | J18: 3 | K18: Adds 2 to the ATK of neighboring monsters. | L18: --- | M18: --- | N18: Neighboring ATK | O18: >On Remove Slice | P18: --- | Q18: (Neighboring ATK): This addition to ATK will always take place after all other calculations and modifiers have been added. | R18: ---
A19: FALSE | B19: FALSE | C19: M | D19: Dragon | E19: 4 | F19: Uncommon | G19: 3 | H19: 1 | I19: 4 | J19: 6 | K19: This unit's ATK damage ignores block. | L19: --- | M19: --- | N19: Initiates [Double ATK or BLK] On Spin | O19: > On Spin | P19: [Double ATK or BLK] | Q19: Once initiated, sets trigger to automatically double the effect of the first time the player gains BLK or deals ATK damage, then removes this trigger. | R19: ---
A20: FALSE | B20: FALSE | C20: I | D20: Throwing Knife | E20: 1 | F20: Starter | G20: 1 | H20: 2 | I20: --- | J20: --- | K20: (ATK 3), OR (ATK 1) and keep this item. | L20: --- | M20: --- | N20: --- | O20: --- | P20: --- | Q20: --- | R20: ---
A21: TRUE | B21: FALSE | C21: I | D21: Shield | E21: 1 | F21: Starter | G21: 1 | H21: 1 | I21: --- | J21: --- | K21: (BLK 4) | L21: --- | M21: --- | N21: --- | O21: --- | P21: --- | Q21: --- | R21: ---
A22: TRUE | B22: FALSE | C22: I | D22: Sai | E22: 2 | F22: Starter | G22: 1 | H22: 2 | I22: --- | J22: --- | K22: (ATK 2), or (ATK 4) against monsters with even ATK. | L22: (Is enemy ATK even?) | M22: >On Spin >On Enemy ATK Change | N22: Its own ATK | O22: >On Spin >On Enemy ATK Change
A23: TRUE | B23: FALSE | C23: I | D23: Medallion | E23: 2 | F23: Starter | G23: 1 | H23: 1 | I23: --- | J23: --- | K23: (BLK 6-X), where X is your HP. | L23: (HP) | M23: >On Spin >On HP Change | N23: Its own BLK | O23: >On Spin >On HP Change | P23: >On HP Change | Q23: This check occurs each time the player's HP changes.
A24: TRUE | B24: FALSE | C24: I | D24: Helmet | E24: 2 | F24: Starter | G24: 1 | H24: 2 | I24: --- | J24: --- | K24: (BLK X), where X is the lowest HP between you and the enemy. | L24: [Lowest HP] | M24: >On Spin >On HP Change >On Enemy HP Change | N24: Its own BLK | O24: >On Spin >On HP Change >On Enemy HP Change | P24: [Lowest HP] | Q24: [Lowest HP]: Compares the player's current HP against the enemy's current HP and takes the lower value as X (or the Player's value if tied). This "check" occurs every time the enemy's HP changes, or the player's HP changes.
A25: TRUE | B25: FALSE | C25: I | D25: Da Boot | E25: 2 | F25: Starter | G25: 1 | H25: 2 | I25: --- | J25: --- | K25: Defeat an enemy with less HP than you. | L25: (Is enemy HP less?) | M25: >On Spin >On HP Change >On Enemy HP Change | N25: (Usable?) | O25: Updates whenver (Is enemy HP less?) updates, to match it. | P25: [Defeat] | Q25: When used, Resolve Combat immediately, skipping ATK/BLK resolution. | R25: ---
A26: TRUE | B26: FALSE | C26: I | D26: Grimoire | E26: 3 | F26: Uncommon | G26: 1 | H26: 1 | I26: --- | J26: --- | K26: (ATK X) equal to the ATK of the last monster faced. | L26: (Last Mob ATK) | M26: (Initial Value) >On Spin | N26: Its own ATK | O26: (Initial Value) >On Spin | P26: (Last Mob ATK) | Q26: Last Mob ATK: On Spin, immediately store the enemy's ATK in this value. Overwrite this value each time On Spin occurs. | R26: This item's Initial Value is always zero (0).
A27: TRUE | B27: FALSE | C27: I | D27: Bloody Gauntlets | E27: 3 | F27: Uncommon | G27: 1 | H27: 1 | I27: --- | J27: --- | K27: (ATK 7-X), where X is your HP. | L27: (HP) | M27: >On Spin >On HP Change | N27: Its own ATK | O27: >On Spin >On HP Change | P27: --- | Q27: --- | R27: ---
A28: FALSE | B28: FALSE | C28: I | D28: Breastplate | E28: 2 | F28: Starter | G28: 2 | H28: 2 | I28: --- | J28: --- | K28: (BLK 2). If you lose HP this combat, keep this item. | L28: (Did lose HP?) | M28: >On Combat Resolve | N28: --- | O28: --- | P28: [Delayed Discard] [Tap] [Untap] | Q28: Delayed Discard: Tap this item on use. By default, this item is Discarded (like most items) On Combat Resolve. If [Did Lose HP?] is met, then Untap the item instead of discarding it. Did Lose HP?: Compare (HP) from On Spin versus On Combat Resolve. If the value is less, then this criterion is met. | R28: Edge Case: If the item Healing Potion was used this combat, then [Did Lose HP?] always returns True.
A29: TRUE | B29: FALSE | C29: I | D29: Bracers | E29: 3 | F29: Starter | G29: 2 | H29: 2 | I29: --- | J29: --- | K29: (BLK X) equal to the ATK of the weakest neighboring enemy. | L29: [Neighbors' lowest ATK] | M29: >On Spin | N29: Its own BLK | O29: >On Spin | P29: --- | Q29: --- | R29: Edge Case: When fighting the final enemy, this item becomes unusable.
A30: FALSE | B30: FALSE | C30: I | D30: Smoke Bomb | E30: 4 | F30: Uncommon | G30: 2 | H30: 1 | I30: --- | J30: --- | K30: Re-roll the encounter, then Gain 1 Random Item. | L30: --- | M30: --- | N30: --- | O30: --- | P30: [Spin Again] [Gain 1 Item] | Q30: Spin Again - Immediately end combat. Do not resolve combat in any way. Spin again, and guarantee that the same slice is not spun again. Gain 1 Item - Draws 1 Random item (tier-agnostic) from the pool of items that have not been drawn in this dungeon yet. | R30: ---
A31: TRUE | B31: FALSE | C31: I | D31: Knucklers | E31: 3 | F31: Starter | G31: 2 | H31: 2 | I31: --- | J31: --- | K31: (ATK 7-X), where X is the number of items you have at the start of combat. | L31: (# Items) | M31: >On Draft >On Spin | N31: Its own ATK | O31: >On Spin >On HP Change >On Enemy HP Change | P31: (HP Delta) | Q31: [HP Delta] - Takes the absolute value (i.e. positive or negative) of the delta between the player and enemy's HP. | R31: ---
A32: TRUE | B32: FALSE | C32: I | D32: Fangs | E32: 4 | F32: Uncommon | G32: 2 | H32: 2 | I32: --- | J32: --- | K32: Receive DMG equal to enemy ATK, then Defeat the enemy and Heal equal to their HP (up to your Max HP). | L32: --- | M32: --- | N32: [Fange DMG] | O32: >On Enemy ATK Change | P32: [Fangs DMG] [Fangs Healing] | Q32: On item use, store (Enemy current HP) to be used later. [Fangs DMG]: When used, immediately receive ATK equal to enemy ATK (this can be blocked, like during Resolve Combat) [Fangs Healing]: Immediately after [Fangs DMG] and after checks like (Player Dead?), Heal equal to (Enemy current HP). Player HP can never exceed 6. | R32: Edge Case: If Fangs is used and it would kill the player, the order of resolution is: [Healing Potion], then [Fangs Healing].
A33: FALSE | B33: FALSE | C33: I | D33: Poison Flask | E33: 4 | F33: Uncommon | G33: 2 | H33: 2 | I33: --- | J33: --- | K33: Choose a neighbor. Once they appear in combat, they lose 5 HP instantly. | L33: --- | M33: --- | N33: [Choose Neighbor] Options | O33: >On Spin | P33: [Choose Neighbor] [Poison] | Q33: [Choose Neighbor] - A prompt appears and allows the player to select a Neighbor to the current enemy. [Poison] - Set a (Poisoned) state on that enemy. When that enemy appears On Spin, they immediately lose 5 HP. This may kill the enemy, which would jump the player straight to Resolve Combat. | R33: Edge Case: If there are 0 neighbors (this is the last enemy), this item is unusable Edge Case: If the player has already used Crossbow on a neighbor, remove them from [Choose Neighbor]. Edge Case: The term "lose HP" is not considered ATK Dmg - in other words, this item can be used to kill Goblin.
A34: TRUE | B34: FALSE | C34: I | D34: Cursed Scroll | E34: 4 | F34: Uncommon | G34: 2 | H34: 1 | I34: --- | J34: --- | K34: At the start of each combat, lose 1 HP. On use, heal your HP to up to full (6). | L34: --- | M34: --- | N34: (HP) | O34: >On Spin | P34: (HP) (Full HP) | Q34: While Cursed Scroll is in the player's inventory (i.e. has not been used), the player will always Lose 1 HP triggered On Spin (after combat has begun). | R34: Edge Case: Losing 1 HP from Cursed Scroll should count for (Did Lose HP?), making this synergistic with Breastplate.
A35: TRUE | B35: FALSE | C35: I | D35: Spiked Flail | E35: 4 | F35: Starter | G35: 3 | H35: 1 | I35: --- | J35: --- | K35: (ATK 2+X), where X is the number of monsters you have defeated. | L35: (# Mob Defeated) | M35: >On Remove Slice | N35: Its own ATK | O35: >On Remove Slice | P35: [Highest HP] | Q35: [Highest HP]: Compares the player's current HP against the enemy's current HP and takes the higher value as X (or the Player's value if tied). This "check" occurs every time the enemy's HP changes, or the player's HP changes.
A36: FALSE | B36: FALSE | C36: I | D36: Healing Potion | E36: 3 | F36: Uncommon | G36: 3 | H36: 1 | I36: --- | J36: --- | K36: Unplayable. When you would die, discard this and heal up to 3 HP. | L36: (HP) (Player Dead?) | M36: >On HP Change | N36: --- | O36: --- | P36: [Healing Potion] | Q36: Healing Potion If player HP ever equals 0, immediately Discard this item and set the player's HP ot 4. | R36: Edge Case: If Fangs is used and it would kill the player, the order of resolution is: [Healing Potion], then [Fangs Healing].
A37: FALSE | B37: FALSE | C37: I | D37: Crossbow | E37: 4 | F37: Uncommon | G37: 3 | H37: 1 | I37: --- | J37: --- | K37: Select a neighbor with 4 or less HP. Defeat them after combat ends. | L37: --- | M37: --- | N37: [Choose Eligible Neighbor] Options | O37: >On Spin >On Crossbow Mark | P37: [Choose Elligible Neighbors] [Crossbow Mark] [Multi-Defeat] | Q37: [Choose Elligible Neighbors] - Like [Choose Neighbor], but only show selectable neighbors based on the criterion (in this case, HP equal to 4 or less). [Crossbow Mark] - Set a (Crossbow Mark) state on the enemy. On Resolve Combat, this enemy will be Defeated. [Multi-Defeat] - On Resolve Combat, it is possible for multiple enemies to be Defeated at once. In this case, perform Remove Slice for the immediate enemy, then perform Remove Slice for neighboring enemies defeated by Crossbow (in any order). | R37: Edge Case: If there are 0 neighbors (this is the last enemy), this item is unusable Edge Case: If the player has already used Poison Flask on a neighbor, remove them from [Choose Elligible Neighbors].
A38: TRUE | B38: FALSE | C38: I | D38: Sledgehammer | E38: 2 | F38: Uncommon | G38: 3 | H38: 1 | I38: --- | J38: --- | K38: Defeat an enemy with 5 or more ATK. | L38: (Is enemy ATK 5+?) | M38: >On Spin >On Enemy ATK Change | N38: (Usable?) | O38: Updates whenver (Is enemy ATK 5+?) updates, to match it. | P38: [Defeat] | Q38: When used, Resolve Combat immediately, skipping ATK/BLK resolution.
A39: FALSE | B39: FALSE | C39: I | D39: Pocketwatch | E39: 3 | F39: Uncommon | G39: 3 | H39: 1 | I39: --- | J39: --- | K39: (ATK X) equal to the ATK of the strongest neighboring enemy. | L39: [Neighbors' highest ATK] | M39: >On Spin | N39: Its own ATK | O39: >On Spin | P39: --- | Q39: --- | R39: Edge Case: When fighting the final enemy, this item becomes unusable.
A40: FALSE | B40: TRUE | C40: I | D40: Dagger | E40: 2 | F40: Starter | G40: 1 | H40: 1 | I40: --- | J40: --- | K40: (ATK 2), then return to your hand. | L40: --- | M40: --- | N40: --- | O40: --- | P40: [Tap] [Untap] | Q40: Do not discard this item on use, but Tap the item. Untap always occurs On Resolve Combat
...

Sheet filter_active_content
A1: Art? | B1: Hide? | C1: Type | D1: Name | E1: Priority | F1: Starter? | G1: Tier | H1: Count | I1: ATK | J1: HP | K1: Ability | L1: Starter? | M1: Updated by... | N1: (when updated) | O1: Updates... | P1: (when updates) | Q1: Special Function | R1: Defined | S1: Exceptions / Edge Cases | T1: Updated | U1: Patch Notes
A2: =IFERROR(__xludf.DUMMYFUNCTION("FILTER('All Content (Mobs, Items)'!A:R,'All Content (Mobs, Items)'!B:B=FALSE)"),TRUE) -> TRUE | B2: =IFERROR(__xludf.DUMMYFUNCTION("""COMPUTED_VALUE"""),FALSE) -> FALSE | C2: =IFERROR(__xludf.DUMMYFUNCTION("""COMPUTED_VALUE"""),"M") -> M | D2: =IFERROR(__xludf.DUMMYFUNCTION("""COMPUTED_VALUE"""),"Wizard") -> Wizard | E2: =IFERROR(__xludf.DUMMYFUNCTION("""COMPUTED_VALUE"""),1.0) -> 1 | F2: =IFERROR(__xludf.DUMMYFUNCTION("""COMPUTED_VALUE"""),"Starter") -> Starter | G2: =IFERROR(__xludf.DUMMYFUNCTION("""COMPUTED_VALUE"""),1.0) -> 1 | H2: =IFERROR(__xludf.DUMMYFUNCTION("""COMPUTED_VALUE"""),2.0) -> 2 | I2: =IFERROR(__xludf.DUMMYFUNCTION("""COMPUTED_VALUE"""),5.0) -> 5 | J2: =IFERROR(__xludf.DUMMYFUNCTION("""COMPUTED_VALUE"""),2.0) -> 2 | K2: =IFERROR(__xludf.DUMMYFUNCTION("""COMPUTED_VALUE"""),"---") -> --- | L2: =IFERROR(__xludf.DUMMYFUNCTION("""COMPUTED_VALUE"""),"---") -> --- | N2: =IFERROR(__xludf.DUMMYFUNCTION("""COMPUTED_VALUE"""),"---") -> --- | O2: =IFERROR(__xludf.DUMMYFUNCTION("""COMPUTED_VALUE"""),"---") -> --- | P2: =IFERROR(__xludf.DUMMYFUNCTION("""COMPUTED_VALUE"""),"---") -> --- | Q2: =IFERROR(__xludf.DUMMYFUNCTION("""COMPUTED_VALUE"""),"---") -> --- | R2: =IFERROR(__xludf.DUMMYFUNCTION("""COMPUTED_VALUE"""),"---") -> ---
A3: =IFERROR(__xludf.DUMMYFUNCTION("""COMPUTED_VALUE"""),TRUE) -> TRUE | B3: =IFERROR(__xludf.DUMMYFUNCTION("""COMPUTED_VALUE"""),FALSE) -> FALSE | C3: =IFERROR(__xludf.DUMMYFUNCTION("""COMPUTED_VALUE"""),"M") -> M | D3: =IFERROR(__xludf.DUMMYFUNCTION("""COMPUTED_VALUE"""),"Golem") -> Golem | E3: =IFERROR(__xludf.DUMMYFUNCTION("""COMPUTED_VALUE"""),1.0) -> 1 | F3: =IFERROR(__xludf.DUMMYFUNCTION("""COMPUTED_VALUE"""),"Starter") -> Starter | G3: =IFERROR(__xludf.DUMMYFUNCTION("""COMPUTED_VALUE"""),1.0) -> 1 | H3: =IFERROR(__xludf.DUMMYFUNCTION("""COMPUTED_VALUE"""),2.0) -> 2 | I3: =IFERROR(__xludf.DUMMYFUNCTION("""COMPUTED_VALUE"""),3.0) -> 3 | J3: =IFERROR(__xludf.DUMMYFUNCTION("""COMPUTED_VALUE"""),7.0) -> 7 | K3: =IFERROR(__xludf.DUMMYFUNCTION("""COMPUTED_VALUE"""),"---") -> --- | L3: =IFERROR(__xludf.DUMMYFUNCTION("""COMPUTED_VALUE"""),"---") -> --- | N3: =IFERROR(__xludf.DUMMYFUNCTION("""COMPUTED_VALUE"""),"---") -> --- | O3: =IFERROR(__xludf.DUMMYFUNCTION("""COMPUTED_VALUE"""),"---") -> --- | P3: =IFERROR(__xludf.DUMMYFUNCTION("""COMPUTED_VALUE"""),"---") -> --- | Q3: =IFERROR(__xludf.DUMMYFUNCTION("""COMPUTED_VALUE"""),"---") -> --- | R3: =IFERROR(__xludf.DUMMYFUNCTION("""COMPUTED_VALUE"""),"---") -> --- | T3: 44671 | U3: HP 6->7
A4: =IFERROR(__xludf.DUMMYFUNCTION("""COMPUTED_VALUE"""),TRUE) -> TRUE | B4: =IFERROR(__xludf.DUMMYFUNCTION("""COMPUTED_VALUE"""),FALSE) -> FALSE | C4: =IFERROR(__xludf.DUMMYFUNCTION("""COMPUTED_VALUE"""),"M") -> M | D4: =IFERROR(__xludf.DUMMYFUNCTION("""COMPUTED_VALUE"""),"Goblin") -> Goblin | E4: =IFERROR(__xludf.DUMMYFUNCTION("""COMPUTED_VALUE"""),3.0) -> 3 | F4: =IFERROR(__xludf.DUMMYFUNCTION("""COMPUTED_VALUE"""),"Starter") -> Starter | G4: =IFERROR(__xludf.DUMMYFUNCTION("""COMPUTED_VALUE"""),1.0) -> 1 | H4: =IFERROR(__xludf.DUMMYFUNCTION("""COMPUTED_VALUE"""),2.0) -> 2 | I4: =IFERROR(__xludf.DUMMYFUNCTION("""COMPUTED_VALUE"""),3.0) -> 3 | J4: =IFERROR(__xludf.DUMMYFUNCTION("""COMPUTED_VALUE"""),1.0) -> 1 | K4: =IFERROR(__xludf.DUMMYFUNCTION("""COMPUTED_VALUE"""),"Cannot receive ATK damage.") -> Cannot receive ATK damage. | L4: =IFERROR(__xludf.DUMMYFUNCTION("""COMPUTED_VALUE"""),"---") -> --- | M4: =IFERROR(__xludf.DUMMYFUNCTION("""COMPUTED_VALUE"""),"---") -> --- | N4: =IFERROR(__xludf.DUMMYFUNCTION("""COMPUTED_VALUE"""),"---") -> --- | O4: =IFERROR(__xludf.DUMMYFUNCTION("""COMPUTED_VALUE"""),"---") -> --- | P4: =IFERROR(__xludf.DUMMYFUNCTION("""COMPUTED_VALUE"""),"(No ATK Dmg)") -> (No ATK Dmg) | Q4: =IFERROR(__xludf.DUMMYFUNCTION("""COMPUTED_VALUE"""),"(No ATK Dmg): This unit's HP can never be reduced. Note that this unit can be defeated through all other means.") -> (No ATK Dmg): This unit's HP can never be reduced. Note that this unit can be defeated through all other means. | R4: =IFERROR(__xludf.DUMMYFUNCTION("""COMPUTED_VALUE"""),"---") -> ---
A5: =IFERROR(__xludf.DUMMYFUNCTION("""COMPUTED_VALUE"""),TRUE) -> TRUE | B5: =IFERROR(__xludf.DUMMYFUNCTION("""COMPUTED_VALUE"""),FALSE) -> FALSE | C5: =IFERROR(__xludf.DUMMYFUNCTION("""COMPUTED_VALUE"""),"M") -> M | D5: =IFERROR(__xludf.DUMMYFUNCTION("""COMPUTED_VALUE"""),"Skeleton") -> Skeleton | E5: =IFERROR(__xludf.DUMMYFUNCTION("""COMPUTED_VALUE"""),3.0) -> 3 | F5: =IFERROR(__xludf.DUMMYFUNCTION("""COMPUTED_VALUE"""),"Starter") -> Starter | G5: =IFERROR(__xludf.DUMMYFUNCTION("""COMPUTED_VALUE"""),1.0) -> 1 | H5: =IFERROR(__xludf.DUMMYFUNCTION("""COMPUTED_VALUE"""),2.0) -> 2 | I5: =IFERROR(__xludf.DUMMYFUNCTION("""COMPUTED_VALUE"""),3.0) -> 3 | J5: =IFERROR(__xludf.DUMMYFUNCTION("""COMPUTED_VALUE"""),"X (3)") -> X (3) | K5: =IFERROR(__xludf.DUMMYFUNCTION("""COMPUTED_VALUE"""),"X = The HP of the last enemy faced.") -> X = The HP of the last enemy faced. | L5: =IFERROR(__xludf.DUMMYFUNCTION("""COMPUTED_VALUE"""),"(HP of last enemy spun)") -> (HP of last enemy spun) | M5: =IFERROR(__xludf.DUMMYFUNCTION("""COMPUTED_VALUE"""),">On Spin") -> >On Spin | N5: =IFERROR(__xludf.DUMMYFUNCTION("""COMPUTED_VALUE"""),"---") -> --- | O5: =IFERROR(__xludf.DUMMYFUNCTION("""COMPUTED_VALUE"""),"---") -> --- | P5: =IFERROR(__xludf.DUMMYFUNCTION("""COMPUTED_VALUE"""),"(Last Mob HP)") -> (Last Mob HP) | Q5: =IFERROR(__xludf.DUMMYFUNCTION("""COMPUTED_VALUE"""),"Last Mob HP: On Spin, immediately store the enemy's HP in this value. Overwrite this value each time On Spin occurs.") -> Last Mob HP: On Spin, immediately store the enemy's HP in this value. Overwrite this value each time On Spin occurs. | R5: =IFERROR(__xludf.DUMMYFUNCTION("""COMPUTED_VALUE"""),"Edge Case: If this is the first unit faced, set HP to 3.") -> Edge Case: If this is the first unit faced, set HP to 3.
A6: =IFERROR(__xludf.DUMMYFUNCTION("""COMPUTED_VALUE"""),TRUE) -> TRUE | B6: =IFERROR(__xludf.DUMMYFUNCTION("""COMPUTED_VALUE"""),FALSE) -> FALSE | C6: =IFERROR(__xludf.DUMMYFUNCTION("""COMPUTED_VALUE"""),"M") -> M | D6: =IFERROR(__xludf.DUMMYFUNCTION("""COMPUTED_VALUE"""),"Hornet Swarm") -> Hornet Swarm | E6: =IFERROR(__xludf.DUMMYFUNCTION("""COMPUTED_VALUE"""),3.0) -> 3 | F6: =IFERROR(__xludf.DUMMYFUNCTION("""COMPUTED_VALUE"""),"Starter") -> Starter | G6: =IFERROR(__xludf.DUMMYFUNCTION("""COMPUTED_VALUE"""),1.0) -> 1 | H6: =IFERROR(__xludf.DUMMYFUNCTION("""COMPUTED_VALUE"""),2.0) -> 2 | I6: =IFERROR(__xludf.DUMMYFUNCTION("""COMPUTED_VALUE"""),2.0) -> 2 | J6: =IFERROR(__xludf.DUMMYFUNCTION("""COMPUTED_VALUE"""),3.0) -> 3 | K6: =IFERROR(__xludf.DUMMYFUNCTION("""COMPUTED_VALUE"""),"This unit attacks twice.") -> This unit attacks twice. | L6: =IFERROR(__xludf.DUMMYFUNCTION("""COMPUTED_VALUE"""),"---") -> --- | M6: =IFERROR(__xludf.DUMMYFUNCTION("""COMPUTED_VALUE"""),"---") -> --- | N6: =IFERROR(__xludf.DUMMYFUNCTION("""COMPUTED_VALUE"""),"---") -> --- | O6: =IFERROR(__xludf.DUMMYFUNCTION("""COMPUTED_VALUE"""),"---") -> --- | P6: =IFERROR(__xludf.DUMMYFUNCTION("""COMPUTED_VALUE"""),"[Attacks Twice]") -> [Attacks Twice] | Q6: =IFERROR(__xludf.DUMMYFUNCTION("""COMPUTED_VALUE"""),"On Resolve Combat, takes its current ATK and deals dmg to the player two times.") -> On Resolve Combat, takes its current ATK and deals dmg to the player two times.
A7: =IFERROR(__xludf.DUMMYFUNCTION("""COMPUTED_VALUE"""),TRUE) -> TRUE | B7: =IFERROR(__xludf.DUMMYFUNCTION("""COMPUTED_VALUE"""),FALSE) -> FALSE | C7: =IFERROR(__xludf.DUMMYFUNCTION("""COMPUTED_VALUE"""),"M") -> M | D7: =IFERROR(__xludf.DUMMYFUNCTION("""COMPUTED_VALUE"""),"Lich") -> Lich | E7: =IFERROR(__xludf.DUMMYFUNCTION("""COMPUTED_VALUE"""),4.0) -> 4 | F7: =IFERROR(__xludf.DUMMYFUNCTION("""COMPUTED_VALUE"""),"Uncommon") -> Uncommon | G7: =IFERROR(__xludf.DUMMYFUNCTION("""COMPUTED_VALUE"""),1.0) -> 1 | H7: =IFERROR(__xludf.DUMMYFUNCTION("""COMPUTED_VALUE"""),2.0) -> 2 | I7: =IFERROR(__xludf.DUMMYFUNCTION("""COMPUTED_VALUE"""),3.0) -> 3 | J7: =IFERROR(__xludf.DUMMYFUNCTION("""COMPUTED_VALUE"""),1.0) -> 1 | K7: =IFERROR(__xludf.DUMMYFUNCTION("""COMPUTED_VALUE"""),"Adds 1 to the HP of neighboring Monsters.") -> Adds 1 to the HP of neighboring Monsters. | L7: =IFERROR(__xludf.DUMMYFUNCTION("""COMPUTED_VALUE"""),"---") -> --- | M7: =IFERROR(__xludf.DUMMYFUNCTION("""COMPUTED_VALUE"""),"---") -> --- | N7: =IFERROR(__xludf.DUMMYFUNCTION("""COMPUTED_VALUE"""),"Neighboring HP") -> Neighboring HP | O7: =IFERROR(__xludf.DUMMYFUNCTION("""COMPUTED_VALUE"""),">On Remove Slice") -> >On Remove Slice | P7: =IFERROR(__xludf.DUMMYFUNCTION("""COMPUTED_VALUE"""),"---") -> --- | Q7: =IFERROR(__xludf.DUMMYFUNCTION("""COMPUTED_VALUE"""),"(Neighboring HP): This addition to HP will always take place after all other calculations and modifiers have been added.") -> (Neighboring HP): This addition to HP will always take place after all other calculations and modifiers have been added. | R7: =IFERROR(__xludf.DUMMYFUNCTION("""COMPUTED_VALUE"""),"---") -> ---
A8: =IFERROR(__xludf.DUMMYFUNCTION("""COMPUTED_VALUE"""),TRUE) -> TRUE | B8: =IFERROR(__xludf.DUMMYFUNCTION("""COMPUTED_VALUE"""),FALSE) -> FALSE | C8: =IFERROR(__xludf.DUMMYFUNCTION("""COMPUTED_VALUE"""),"M") -> M | D8: =IFERROR(__xludf.DUMMYFUNCTION("""COMPUTED_VALUE"""),"Ogre") -> Ogre | E8: =IFERROR(__xludf.DUMMYFUNCTION("""COMPUTED_VALUE"""),1.0) -> 1 | F8: =IFERROR(__xludf.DUMMYFUNCTION("""COMPUTED_VALUE"""),"Starter") -> Starter | G8: =IFERROR(__xludf.DUMMYFUNCTION("""COMPUTED_VALUE"""),2.0) -> 2 | H8: =IFERROR(__xludf.DUMMYFUNCTION("""COMPUTED_VALUE"""),2.0) -> 2 | I8: =IFERROR(__xludf.DUMMYFUNCTION("""COMPUTED_VALUE"""),4.0) -> 4 | J8: =IFERROR(__xludf.DUMMYFUNCTION("""COMPUTED_VALUE"""),"X") -> X | K8: =IFERROR(__xludf.DUMMYFUNCTION("""COMPUTED_VALUE"""),"X = Your HP at the start of combat.") -> X = Your HP at the start of combat. | L8: =IFERROR(__xludf.DUMMYFUNCTION("""COMPUTED_VALUE"""),"(HP)") -> (HP) | M8: =IFERROR(__xludf.DUMMYFUNCTION("""COMPUTED_VALUE"""),">On Spin") -> >On Spin | N8: =IFERROR(__xludf.DUMMYFUNCTION("""COMPUTED_VALUE"""),"---") -> --- | O8: =IFERROR(__xludf.DUMMYFUNCTION("""COMPUTED_VALUE"""),"---") -> --- | P8: =IFERROR(__xludf.DUMMYFUNCTION("""COMPUTED_VALUE"""),"---") -> --- | Q8: =IFERROR(__xludf.DUMMYFUNCTION("""COMPUTED_VALUE"""),"---") -> --- | R8: =IFERROR(__xludf.DUMMYFUNCTION("""COMPUTED_VALUE"""),"---") -> --- | T8: 44675 | U8: Rework: changed HP to "X=Your HP at the start of combat"
A9: =IFERROR(__xludf.DUMMYFUNCTION("""COMPUTED_VALUE"""),TRUE) -> TRUE | B9: =IFERROR(__xludf.DUMMYFUNCTION("""COMPUTED_VALUE"""),FALSE) -> FALSE | C9: =IFERROR(__xludf.DUMMYFUNCTION("""COMPUTED_VALUE"""),"M") -> M | D9: =IFERROR(__xludf.DUMMYFUNCTION("""COMPUTED_VALUE"""),"Berserker") -> Berserker | E9: =IFERROR(__xludf.DUMMYFUNCTION("""COMPUTED_VALUE"""),2.0) -> 2 | F9: =IFERROR(__xludf.DUMMYFUNCTION("""COMPUTED_VALUE"""),"Starter") -> Starter | G9: =IFERROR(__xludf.DUMMYFUNCTION("""COMPUTED_VALUE"""),2.0) -> 2 | H9: =IFERROR(__xludf.DUMMYFUNCTION("""COMPUTED_VALUE"""),1.0) -> 1 | I9: =IFERROR(__xludf.DUMMYFUNCTION("""COMPUTED_VALUE"""),"(1+X)") -> (1+X) | J9: =IFERROR(__xludf.DUMMYFUNCTION("""COMPUTED_VALUE"""),"(2+X)") -> (2+X) | K9: =IFERROR(__xludf.DUMMYFUNCTION("""COMPUTED_VALUE"""),"X = The number of monsters you have defeated.") -> X = The number of monsters you have defeated. | L9: =IFERROR(__xludf.DUMMYFUNCTION("""COMPUTED_VALUE"""),"(# Mob Defeated)") -> (# Mob Defeated) | M9: =IFERROR(__xludf.DUMMYFUNCTION("""COMPUTED_VALUE"""),">On Remove Slice") -> >On Remove Slice | N9: =IFERROR(__xludf.DUMMYFUNCTION("""COMPUTED_VALUE"""),"---") -> --- | O9: =IFERROR(__xludf.DUMMYFUNCTION("""COMPUTED_VALUE"""),"---") -> --- | P9: =IFERROR(__xludf.DUMMYFUNCTION("""COMPUTED_VALUE"""),"(# Mobs Defeated)") -> (# Mobs Defeated) | Q9: =IFERROR(__xludf.DUMMYFUNCTION("""COMPUTED_VALUE"""),"(# Mobs Defeated): Every time a slice is removed after the initial drafting phase, this increments.") -> (# Mobs Defeated): Every time a slice is removed after the initial drafting phase, this increments. | R9: =IFERROR(__xludf.DUMMYFUNCTION("""COMPUTED_VALUE"""),"---") -> --- | T9: 44679 | U9: (5/2) - Nerfed to (1+X) for ATK (4/24) - Rework: changed ATK and HP to (3+X), where X=Number of Mobs defeated
A10: =IFERROR(__xludf.DUMMYFUNCTION("""COMPUTED_VALUE"""),TRUE) -> TRUE | B10: =IFERROR(__xludf.DUMMYFUNCTION("""COMPUTED_VALUE"""),FALSE) -> FALSE | C10: =IFERROR(__xludf.DUMMYFUNCTION("""COMPUTED_VALUE"""),"M") -> M | D10: =IFERROR(__xludf.DUMMYFUNCTION("""COMPUTED_VALUE"""),"Dire Wolf") -> Dire Wolf | E10: =IFERROR(__xludf.DUMMYFUNCTION("""COMPUTED_VALUE"""),2.0) -> 2 | F10: =IFERROR(__xludf.DUMMYFUNCTION("""COMPUTED_VALUE"""),"Starter") -> Starter | G10: =IFERROR(__xludf.DUMMYFUNCTION("""COMPUTED_VALUE"""),2.0) -> 2 | H10: =IFERROR(__xludf.DUMMYFUNCTION("""COMPUTED_VALUE"""),2.0) -> 2 | I10: =IFERROR(__xludf.DUMMYFUNCTION("""COMPUTED_VALUE"""),"X") -> X | J10: =IFERROR(__xludf.DUMMYFUNCTION("""COMPUTED_VALUE"""),3.0) -> 3 | K10: =IFERROR(__xludf.DUMMYFUNCTION("""COMPUTED_VALUE"""),"X = Your HP at the start of combat.") -> X = Your HP at the start of combat. | L10: =IFERROR(__xludf.DUMMYFUNCTION("""COMPUTED_VALUE"""),"(HP)") -> (HP) | M10: =IFERROR(__xludf.DUMMYFUNCTION("""COMPUTED_VALUE"""),">On Spin") -> >On Spin | N10: =IFERROR(__xludf.DUMMYFUNCTION("""COMPUTED_VALUE"""),"---") -> --- | O10: =IFERROR(__xludf.DUMMYFUNCTION("""COMPUTED_VALUE"""),"---") -> --- | P10: =IFERROR(__xludf.DUMMYFUNCTION("""COMPUTED_VALUE"""),"---") -> --- | Q10: =IFERROR(__xludf.DUMMYFUNCTION("""COMPUTED_VALUE"""),"---") -> --- | R10: =IFERROR(__xludf.DUMMYFUNCTION("""COMPUTED_VALUE"""),"---") -> ---
A11: =IFERROR(__xludf.DUMMYFUNCTION("""COMPUTED_VALUE"""),TRUE) -> TRUE | B11: =IFERROR(__xludf.DUMMYFUNCTION("""COMPUTED_VALUE"""),FALSE) -> FALSE | C11: =IFERROR(__xludf.DUMMYFUNCTION("""COMPUTED_VALUE"""),"M") -> M | D11: =IFERROR(__xludf.DUMMYFUNCTION("""COMPUTED_VALUE"""),"Bandit") -> Bandit | E11: =IFERROR(__xludf.DUMMYFUNCTION("""COMPUTED_VALUE"""),2.0) -> 2 | F11: =IFERROR(__xludf.DUMMYFUNCTION("""COMPUTED_VALUE"""),"Uncommon") -> Uncommon | G11: =IFERROR(__xludf.DUMMYFUNCTION("""COMPUTED_VALUE"""),2.0) -> 2 | H11: =IFERROR(__xludf.DUMMYFUNCTION("""COMPUTED_VALUE"""),2.0) -> 2 | I11: =IFERROR(__xludf.DUMMYFUNCTION("""COMPUTED_VALUE"""),"X") -> X | J11: =IFERROR(__xludf.DUMMYFUNCTION("""COMPUTED_VALUE"""),3.0) -> 3 | K11: =IFERROR(__xludf.DUMMYFUNCTION("""COMPUTED_VALUE"""),"X = The number of items you have at the start of combat.") -> X = The number of items you have at the start of combat. | L11: =IFERROR(__xludf.DUMMYFUNCTION("""COMPUTED_VALUE"""),"(# Items)") -> (# Items) | M11: =IFERROR(__xludf.DUMMYFUNCTION("""COMPUTED_VALUE"""),">On Draft >On Spin") -> >On Draft >On Spin | N11: =IFERROR(__xludf.DUMMYFUNCTION("""COMPUTED_VALUE"""),"---") -> --- | O11: =IFERROR(__xludf.DUMMYFUNCTION("""COMPUTED_VALUE"""),"---") -> --- | P11: =IFERROR(__xludf.DUMMYFUNCTION("""COMPUTED_VALUE"""),"---") -> --- | Q11: =IFERROR(__xludf.DUMMYFUNCTION("""COMPUTED_VALUE"""),"---") -> --- | R11: =IFERROR(__xludf.DUMMYFUNCTION("""COMPUTED_VALUE"""),"---") -> ---
A12: =IFERROR(__xludf.DUMMYFUNCTION("""COMPUTED_VALUE"""),FALSE) -> FALSE | B12: =IFERROR(__xludf.DUMMYFUNCTION("""COMPUTED_VALUE"""),FALSE) -> FALSE | C12: =IFERROR(__xludf.DUMMYFUNCTION("""COMPUTED_VALUE"""),"M") -> M | D12: =IFERROR(__xludf.DUMMYFUNCTION("""COMPUTED_VALUE"""),"Leech League") -> Leech League | E12: =IFERROR(__xludf.DUMMYFUNCTION("""COMPUTED_VALUE"""),2.0) -> 2 | F12: =IFERROR(__xludf.DUMMYFUNCTION("""COMPUTED_VALUE"""),"Uncommon") -> Uncommon | G12: =IFERROR(__xludf.DUMMYFUNCTION("""COMPUTED_VALUE"""),2.0) -> 2 | H12: =IFERROR(__xludf.DUMMYFUNCTION("""COMPUTED_VALUE"""),1.0) -> 1 | I12: =IFERROR(__xludf.DUMMYFUNCTION("""COMPUTED_VALUE"""),4.0) -> 4 | J12: =IFERROR(__xludf.DUMMYFUNCTION("""COMPUTED_VALUE"""),"(1+X)") -> (1+X) | K12: =IFERROR(__xludf.DUMMYFUNCTION("""COMPUTED_VALUE"""),"X = The number of monsters still in play.") -> X = The number of monsters still in play. | L12: =IFERROR(__xludf.DUMMYFUNCTION("""COMPUTED_VALUE"""),"(# mobs)") -> (# mobs) | M12: =IFERROR(__xludf.DUMMYFUNCTION("""COMPUTED_VALUE"""),">On Remove Slice") -> >On Remove Slice | N12: =IFERROR(__xludf.DUMMYFUNCTION("""COMPUTED_VALUE"""),"---") -> --- | O12: =IFERROR(__xludf.DUMMYFUNCTION("""COMPUTED_VALUE"""),"---") -> --- | P12: =IFERROR(__xludf.DUMMYFUNCTION("""COMPUTED_VALUE"""),"---") -> --- | Q12: =IFERROR(__xludf.DUMMYFUNCTION("""COMPUTED_VALUE"""),"---") -> --- | R12: =IFERROR(__xludf.DUMMYFUNCTION("""COMPUTED_VALUE"""),"---") -> --- | T12: 44671 | U12: Rework: changed HP to (1+X), where X=Number of Mobs
A13: =IFERROR(__xludf.DUMMYFUNCTION("""COMPUTED_VALUE"""),TRUE) -> TRUE | B13: =IFERROR(__xludf.DUMMYFUNCTION("""COMPUTED_VALUE"""),FALSE) -> FALSE | C13: =IFERROR(__xludf.DUMMYFUNCTION("""COMPUTED_VALUE"""),"M") -> M | D13: =IFERROR(__xludf.DUMMYFUNCTION("""COMPUTED_VALUE"""),"Wraith") -> Wraith | E13: =IFERROR(__xludf.DUMMYFUNCTION("""COMPUTED_VALUE"""),3.0) -> 3 | F13: =IFERROR(__xludf.DUMMYFUNCTION("""COMPUTED_VALUE"""),"Uncommon") -> Uncommon | G13: =IFERROR(__xludf.DUMMYFUNCTION("""COMPUTED_VALUE"""),2.0) -> 2 | H13: =IFERROR(__xludf.DUMMYFUNCTION("""COMPUTED_VALUE"""),2.0) -> 2 | I13: =IFERROR(__xludf.DUMMYFUNCTION("""COMPUTED_VALUE"""),3.0) -> 3 | J13: =IFERROR(__xludf.DUMMYFUNCTION("""COMPUTED_VALUE"""),3.0) -> 3 | K13: =IFERROR(__xludf.DUMMYFUNCTION("""COMPUTED_VALUE"""),"If a neighbor has higher ATK, then this unit's ATK will match it.") -> If a neighbor has higher ATK, then this unit's ATK will match it. | L13: =IFERROR(__xludf.DUMMYFUNCTION("""COMPUTED_VALUE"""),"[Neighbors' highest ATK]") -> [Neighbors' highest ATK] | M13: =IFERROR(__xludf.DUMMYFUNCTION("""COMPUTED_VALUE"""),">On Remove Slice") -> >On Remove Slice | N13: =IFERROR(__xludf.DUMMYFUNCTION("""COMPUTED_VALUE"""),"Its own ATK") -> Its own ATK | O13: =IFERROR(__xludf.DUMMYFUNCTION("""COMPUTED_VALUE"""),">On Remove Slice") -> >On Remove Slice | P13: =IFERROR(__xludf.DUMMYFUNCTION("""COMPUTED_VALUE"""),"---") -> --- | Q13: =IFERROR(__xludf.DUMMYFUNCTION("""COMPUTED_VALUE"""),"Resolve Order: This is the only function whose order of operations matters. Wraith will check the ATK of others (with their complete modifiers, if any) and ""match"" higher ATK if applicable, and then will receive the ATK increase from Captain.") -> Resolve Order: This is the only function whose order of operations matters. Wraith will check the ATK of others (with their complete modifiers, if any) and "match" higher ATK if applicable, and then will receive the ATK increase from Captain. | R13: =IFERROR(__xludf.DUMMYFUNCTION("""COMPUTED_VALUE"""),"---") -> --- | T13: 44675 | U13: (Slight) Rework: Set base ATK to 3, then added ability for it to match Neighbor's ATK if higher.
A14: =IFERROR(__xludf.DUMMYFUNCTION("""COMPUTED_VALUE"""),FALSE) -> FALSE | B14: =IFERROR(__xludf.DUMMYFUNCTION("""COMPUTED_VALUE"""),FALSE) -> FALSE | C14: =IFERROR(__xludf.DUMMYFUNCTION("""COMPUTED_VALUE"""),"M") -> M | D14: =IFERROR(__xludf.DUMMYFUNCTION("""COMPUTED_VALUE"""),"Mimic") -> Mimic | E14: =IFERROR(__xludf.DUMMYFUNCTION("""COMPUTED_VALUE"""),4.0) -> 4 | F14: =IFERROR(__xludf.DUMMYFUNCTION("""COMPUTED_VALUE"""),"Uncommon") -> Uncommon | G14: =IFERROR(__xludf.DUMMYFUNCTION("""COMPUTED_VALUE"""),2.0) -> 2 | H14: =IFERROR(__xludf.DUMMYFUNCTION("""COMPUTED_VALUE"""),1.0) -> 1 | I14: =IFERROR(__xludf.DUMMYFUNCTION("""COMPUTED_VALUE"""),4.0) -> 4 | J14: =IFERROR(__xludf.DUMMYFUNCTION("""COMPUTED_VALUE"""),5.0) -> 5 | K14: =IFERROR(__xludf.DUMMYFUNCTION("""COMPUTED_VALUE"""),"If this unit is defeated before it can attack, Gain 1 random item.") -> If this unit is defeated before it can attack, Gain 1 random item. | L14: =IFERROR(__xludf.DUMMYFUNCTION("""COMPUTED_VALUE"""),"(Did it attack?)") -> (Did it attack?) | M14: =IFERROR(__xludf.DUMMYFUNCTION("""COMPUTED_VALUE"""),">On Resolve Combat") -> >On Resolve Combat | N14: =IFERROR(__xludf.DUMMYFUNCTION("""COMPUTED_VALUE"""),"Initiates [Gain 1 Item] If (Did it attack?) returns False") -> Initiates [Gain 1 Item] If (Did it attack?) returns False | O14: =IFERROR(__xludf.DUMMYFUNCTION("""COMPUTED_VALUE"""),">On Resolve Combat") -> >On Resolve Combat | P14: =IFERROR(__xludf.DUMMYFUNCTION("""COMPUTED_VALUE"""),"(Did it attack?) [Gain 1 Item]") -> (Did it attack?) [Gain 1 Item] | Q14: =IFERROR(__xludf.DUMMYFUNCTION("""COMPUTED_VALUE"""),"(Did It Attack?): Set to False at the start of combat. If the enemy ever attacks, set to True. Ways to prevent the enemy from attacking are killing or otherwise defeating the enemy with items (i.e. not blocking). Draws 1 Random item (tier-agnostic) from "&"the pool of items that have not been drawn in this dungeon yet.") -> (Did It Attack?): Set to False at the start of combat. If the enemy ever attacks, set to True. Ways to prevent the enemy from attacking are killing or otherwise defeating the enemy with items (i.e. not blocking). Draws 1 Random item (tier-agnostic) from the pool of items that have not been drawn in this dungeon yet. | R14: =IFERROR(__xludf.DUMMYFUNCTION("""COMPUTED_VALUE"""),"Edge Case: If there are 0 items left in the pool, then do not draw an item.") -> Edge Case: If there are 0 items left in the pool, then do not draw an item. | T14: 44671 | U14: Rework: Mimic now only gives item if it is defeated before it can attack.
A15: =IFERROR(__xludf.DUMMYFUNCTION("""COMPUTED_VALUE"""),FALSE) -> FALSE | B15: =IFERROR(__xludf.DUMMYFUNCTION("""COMPUTED_VALUE"""),FALSE) -> FALSE | C15: =IFERROR(__xludf.DUMMYFUNCTION("""COMPUTED_VALUE"""),"M") -> M | D15: =IFERROR(__xludf.DUMMYFUNCTION("""COMPUTED_VALUE"""),"Two-Headed Serpent") -> Two-Headed Serpent | E15: =IFERROR(__xludf.DUMMYFUNCTION("""COMPUTED_VALUE"""),4.0) -> 4 | F15: =IFERROR(__xludf.DUMMYFUNCTION("""COMPUTED_VALUE"""),"Starter") -> Starter | G15: =IFERROR(__xludf.DUMMYFUNCTION("""COMPUTED_VALUE"""),2.0) -> 2 | H15: =IFERROR(__xludf.DUMMYFUNCTION("""COMPUTED_VALUE"""),1.0) -> 1 | I15: =IFERROR(__xludf.DUMMYFUNCTION("""COMPUTED_VALUE"""),5.0) -> 5 | J15: =IFERROR(__xludf.DUMMYFUNCTION("""COMPUTED_VALUE"""),5.0) -> 5 | K15: =IFERROR(__xludf.DUMMYFUNCTION("""COMPUTED_VALUE"""),"Does not attack if you use at least 2 items.") -> Does not attack if you use at least 2 items. | L15: =IFERROR(__xludf.DUMMYFUNCTION("""COMPUTED_VALUE"""),"(# items used this combat)") -> (# items used this combat) | M15: =IFERROR(__xludf.DUMMYFUNCTION("""COMPUTED_VALUE"""),">On Item Use") -> >On Item Use | N15: =IFERROR(__xludf.DUMMYFUNCTION("""COMPUTED_VALUE"""),"---") -> --- | O15: =IFERROR(__xludf.DUMMYFUNCTION("""COMPUTED_VALUE"""),"---") -> --- | P15: =IFERROR(__xludf.DUMMYFUNCTION("""COMPUTED_VALUE"""),"[Used 2 Items?]") -> [Used 2 Items?] | Q15: =IFERROR(__xludf.DUMMYFUNCTION("""COMPUTED_VALUE"""),"Checks if player uses (or 'taps') 2 items during its combat, at which point its ATK immediately drops to zero (0).") -> Checks if player uses (or 'taps') 2 items during its combat, at which point its ATK immediately drops to zero (0). | R15: =IFERROR(__xludf.DUMMYFUNCTION("""COMPUTED_VALUE""")," Edge Case: If the second item used is Smoke Bomb, nothing special happens. Smoke Bomb occurs as usual, and (later) when the player encounters Two-Headed Serpent again, they will still be set to attack again.") -> Edge Case: If the second item used is Smoke Bomb, nothing special happens. Smoke Bomb occurs as usual, and (later) when the player encounters Two-Headed Serpent again, they will still be set to attack again.
A16: =IFERROR(__xludf.DUMMYFUNCTION("""COMPUTED_VALUE"""),FALSE) -> FALSE | B16: =IFERROR(__xludf.DUMMYFUNCTION("""COMPUTED_VALUE"""),FALSE) -> FALSE | C16: =IFERROR(__xludf.DUMMYFUNCTION("""COMPUTED_VALUE"""),"M") -> M | D16: =IFERROR(__xludf.DUMMYFUNCTION("""COMPUTED_VALUE"""),"Slime Boss") -> Slime Boss | E16: =IFERROR(__xludf.DUMMYFUNCTION("""COMPUTED_VALUE"""),2.0) -> 2 | F16: =IFERROR(__xludf.DUMMYFUNCTION("""COMPUTED_VALUE"""),"Starter") -> Starter | G16: =IFERROR(__xludf.DUMMYFUNCTION("""COMPUTED_VALUE"""),3.0) -> 3 | H16: =IFERROR(__xludf.DUMMYFUNCTION("""COMPUTED_VALUE"""),1.0) -> 1 | I16: =IFERROR(__xludf.DUMMYFUNCTION("""COMPUTED_VALUE"""),"X") -> X | J16: =IFERROR(__xludf.DUMMYFUNCTION("""COMPUTED_VALUE"""),9.0) -> 9 | K16: =IFERROR(__xludf.DUMMYFUNCTION("""COMPUTED_VALUE"""),"X = This unit's HP.") -> X = This unit's HP. | L16: =IFERROR(__xludf.DUMMYFUNCTION("""COMPUTED_VALUE"""),"(Enemy HP)") -> (Enemy HP) | M16: =IFERROR(__xludf.DUMMYFUNCTION("""COMPUTED_VALUE"""),">On Enemy HP Change") -> >On Enemy HP Change | N16: =IFERROR(__xludf.DUMMYFUNCTION("""COMPUTED_VALUE"""),"Its own ATK") -> Its own ATK | O16: =IFERROR(__xludf.DUMMYFUNCTION("""COMPUTED_VALUE"""),">On Enemy HP Change") -> >On Enemy HP Change | R16: =IFERROR(__xludf.DUMMYFUNCTION("""COMPUTED_VALUE"""),"Edge Case: This is the only unit whose ATK value can change mid-combat. This means that dealing it damage can effect items that react to enemy ATK (Sai, Fangs, Sledgehammer).") -> Edge Case: This is the only unit whose ATK value can change mid-combat. This means that dealing it damage can effect items that react to enemy ATK (Sai, Fangs, Sledgehammer).
A17: =IFERROR(__xludf.DUMMYFUNCTION("""COMPUTED_VALUE"""),FALSE) -> FALSE | B17: =IFERROR(__xludf.DUMMYFUNCTION("""COMPUTED_VALUE"""),FALSE) -> FALSE | C17: =IFERROR(__xludf.DUMMYFUNCTION("""COMPUTED_VALUE"""),"M") -> M | D17: =IFERROR(__xludf.DUMMYFUNCTION("""COMPUTED_VALUE"""),"Spider Queen") -> Spider Queen | E17: =IFERROR(__xludf.DUMMYFUNCTION("""COMPUTED_VALUE"""),3.0) -> 3 | F17: =IFERROR(__xludf.DUMMYFUNCTION("""COMPUTED_VALUE"""),"Uncommon") -> Uncommon | G17: =IFERROR(__xludf.DUMMYFUNCTION("""COMPUTED_VALUE"""),3.0) -> 3 | H17: =IFERROR(__xludf.DUMMYFUNCTION("""COMPUTED_VALUE"""),1.0) -> 1 | I17: =IFERROR(__xludf.DUMMYFUNCTION("""COMPUTED_VALUE"""),3.0) -> 3 | J17: =IFERROR(__xludf.DUMMYFUNCTION("""COMPUTED_VALUE"""),7.0) -> 7 | K17: =IFERROR(__xludf.DUMMYFUNCTION("""COMPUTED_VALUE"""),"When this unit attacks, if it has more HP than at least one neighbor it attacks twice.") -> When this unit attacks, if it has more HP than at least one neighbor it attacks twice. | L17: =IFERROR(__xludf.DUMMYFUNCTION("""COMPUTED_VALUE"""),"(Neighbor with less HP?)") -> (Neighbor with less HP?) | M17: =IFERROR(__xludf.DUMMYFUNCTION("""COMPUTED_VALUE"""),">On Enemy HP Change") -> >On Enemy HP Change | N17: =IFERROR(__xludf.DUMMYFUNCTION("""COMPUTED_VALUE"""),"(# Times Attack)") -> (# Times Attack) | O17: =IFERROR(__xludf.DUMMYFUNCTION("""COMPUTED_VALUE"""),">On Resolve Combat") -> >On Resolve Combat | P17: =IFERROR(__xludf.DUMMYFUNCTION("""COMPUTED_VALUE"""),"(Neighbor with less HP?)") -> (Neighbor with less HP?) | Q17: =IFERROR(__xludf.DUMMYFUNCTION("""COMPUTED_VALUE"""),"Each time On Enemy HP Change, checks all Neigbors to see if they have less HP than. If True, then sets (# Times Attack) to 2.") -> Each time On Enemy HP Change, checks all Neigbors to see if they have less HP than. If True, then sets (# Times Attack) to 2. | R17: =IFERROR(__xludf.DUMMYFUNCTION("""COMPUTED_VALUE"""),"---") -> --- | T17: 44675 | U17: Rework: Changed HP & ATK, created "Attacks Twice" condition
A18: =IFERROR(__xludf.DUMMYFUNCTION("""COMPUTED_VALUE"""),TRUE) -> TRUE | B18: =IFERROR(__xludf.DUMMYFUNCTION("""COMPUTED_VALUE"""),FALSE) -> FALSE | C18: =IFERROR(__xludf.DUMMYFUNCTION("""COMPUTED_VALUE"""),"M") -> M | D18: =IFERROR(__xludf.DUMMYFUNCTION("""COMPUTED_VALUE"""),"Commander") -> Commander | E18: =IFERROR(__xludf.DUMMYFUNCTION("""COMPUTED_VALUE"""),4.0) -> 4 | F18: =IFERROR(__xludf.DUMMYFUNCTION("""COMPUTED_VALUE"""),"Uncommon") -> Uncommon | G18: =IFERROR(__xludf.DUMMYFUNCTION("""COMPUTED_VALUE"""),3.0) -> 3 | H18: =IFERROR(__xludf.DUMMYFUNCTION("""COMPUTED_VALUE"""),2.0) -> 2 | I18: =IFERROR(__xludf.DUMMYFUNCTION("""COMPUTED_VALUE"""),3.0) -> 3 | J18: =IFERROR(__xludf.DUMMYFUNCTION("""COMPUTED_VALUE"""),3.0) -> 3 | K18: =IFERROR(__xludf.DUMMYFUNCTION("""COMPUTED_VALUE"""),"Adds 2 to the ATK of neighboring monsters.") -> Adds 2 to the ATK of neighboring monsters. | L18: =IFERROR(__xludf.DUMMYFUNCTION("""COMPUTED_VALUE"""),"---") -> --- | M18: =IFERROR(__xludf.DUMMYFUNCTION("""COMPUTED_VALUE"""),"---") -> --- | N18: =IFERROR(__xludf.DUMMYFUNCTION("""COMPUTED_VALUE"""),"Neighboring ATK") -> Neighboring ATK | O18: =IFERROR(__xludf.DUMMYFUNCTION("""COMPUTED_VALUE"""),">On Remove Slice") -> >On Remove Slice | P18: =IFERROR(__xludf.DUMMYFUNCTION("""COMPUTED_VALUE"""),"---") -> --- | Q18: =IFERROR(__xludf.DUMMYFUNCTION("""COMPUTED_VALUE"""),"(Neighboring ATK): This addition to ATK will always take place after all other calculations and modifiers have been added.") -> (Neighboring ATK): This addition to ATK will always take place after all other calculations and modifiers have been added. | R18: =IFERROR(__xludf.DUMMYFUNCTION("""COMPUTED_VALUE"""),"---") -> --- | T18: 44675 | U18: Rework: removed "Double Item" and instead created "Double ATK/BLK" function. Changed HP and ATK to 10
A19: =IFERROR(__xludf.DUMMYFUNCTION("""COMPUTED_VALUE"""),FALSE) -> FALSE | B19: =IFERROR(__xludf.DUMMYFUNCTION("""COMPUTED_VALUE"""),FALSE) -> FALSE | C19: =IFERROR(__xludf.DUMMYFUNCTION("""COMPUTED_VALUE"""),"M") -> M | D19: =IFERROR(__xludf.DUMMYFUNCTION("""COMPUTED_VALUE"""),"Dragon") -> Dragon | E19: =IFERROR(__xludf.DUMMYFUNCTION("""COMPUTED_VALUE"""),4.0) -> 4 | F19: =IFERROR(__xludf.DUMMYFUNCTION("""COMPUTED_VALUE"""),"Uncommon") -> Uncommon | G19: =IFERROR(__xludf.DUMMYFUNCTION("""COMPUTED_VALUE"""),3.0) -> 3 | H19: =IFERROR(__xludf.DUMMYFUNCTION("""COMPUTED_VALUE"""),1.0) -> 1 | I19: =IFERROR(__xludf.DUMMYFUNCTION("""COMPUTED_VALUE"""),4.0) -> 4 | J19: =IFERROR(__xludf.DUMMYFUNCTION("""COMPUTED_VALUE"""),6.0) -> 6 | K19: =IFERROR(__xludf.DUMMYFUNCTION("""COMPUTED_VALUE"""),"This unit's ATK damage ignores block.") -> This unit's ATK damage ignores block. | L19: =IFERROR(__xludf.DUMMYFUNCTION("""COMPUTED_VALUE"""),"---") -> --- | M19: =IFERROR(__xludf.DUMMYFUNCTION("""COMPUTED_VALUE"""),"---") -> --- | N19: =IFERROR(__xludf.DUMMYFUNCTION("""COMPUTED_VALUE"""),"Initiates [Double ATK or BLK] On Spin") -> Initiates [Double ATK or BLK] On Spin | O19: =IFERROR(__xludf.DUMMYFUNCTION("""COMPUTED_VALUE"""),"> On Spin") -> > On Spin | P19: =IFERROR(__xludf.DUMMYFUNCTION("""COMPUTED_VALUE"""),"[Double ATK or BLK]") -> [Double ATK or BLK] | Q19: =IFERROR(__xludf.DUMMYFUNCTION("""COMPUTED_VALUE"""),"Once initiated, sets trigger to automatically double the effect of the first time the player gains BLK or deals ATK damage, then removes this trigger.") -> Once initiated, sets trigger to automatically double the effect of the first time the player gains BLK or deals ATK damage, then removes this trigger. | R19: =IFERROR(__xludf.DUMMYFUNCTION("""COMPUTED_VALUE"""),"---") -> --- | T19: 44675 | U19: Rework: removed "Double Item" and instead created "Double ATK/BLK" function. Changed HP and ATK to 10
A20: =IFERROR(__xludf.DUMMYFUNCTION("""COMPUTED_VALUE"""),FALSE) -> FALSE | B20: =IFERROR(__xludf.DUMMYFUNCTION("""COMPUTED_VALUE"""),FALSE) -> FALSE | C20: =IFERROR(__xludf.DUMMYFUNCTION("""COMPUTED_VALUE"""),"I") -> I | D20: =IFERROR(__xludf.DUMMYFUNCTION("""COMPUTED_VALUE"""),"Throwing Knife") -> Throwing Knife | E20: =IFERROR(__xludf.DUMMYFUNCTION("""COMPUTED_VALUE"""),1.0) -> 1 | F20: =IFERROR(__xludf.DUMMYFUNCTION("""COMPUTED_VALUE"""),"Starter") -> Starter | G20: =IFERROR(__xludf.DUMMYFUNCTION("""COMPUTED_VALUE"""),1.0) -> 1 | H20: =IFERROR(__xludf.DUMMYFUNCTION("""COMPUTED_VALUE"""),2.0) -> 2 | I20: =IFERROR(__xludf.DUMMYFUNCTION("""COMPUTED_VALUE"""),"---") -> --- | J20: =IFERROR(__xludf.DUMMYFUNCTION("""COMPUTED_VALUE"""),"---") -> --- | K20: =IFERROR(__xludf.DUMMYFUNCTION("""COMPUTED_VALUE"""),"(ATK 3), OR (ATK 1) and keep this item.") -> (ATK 3), OR (ATK 1) and keep this item. | L20: =IFERROR(__xludf.DUMMYFUNCTION("""COMPUTED_VALUE"""),"---") -> --- | M20: =IFERROR(__xludf.DUMMYFUNCTION("""COMPUTED_VALUE"""),"---") -> --- | N20: =IFERROR(__xludf.DUMMYFUNCTION("""COMPUTED_VALUE"""),"---") -> --- | O20: =IFERROR(__xludf.DUMMYFUNCTION("""COMPUTED_VALUE"""),"---") -> --- | P20: =IFERROR(__xludf.DUMMYFUNCTION("""COMPUTED_VALUE"""),"---") -> --- | Q20: =IFERROR(__xludf.DUMMYFUNCTION("""COMPUTED_VALUE"""),"---") -> --- | R20: =IFERROR(__xludf.DUMMYFUNCTION("""COMPUTED_VALUE"""),"---") -> --- | T20: 44671 | U20: Rework: Combined "Sword" and "Dagger" into this item.
A21: =IFERROR(__xludf.DUMMYFUNCTION("""COMPUTED_VALUE"""),TRUE) -> TRUE | B21: =IFERROR(__xludf.DUMMYFUNCTION("""COMPUTED_VALUE"""),FALSE) -> FALSE | C21: =IFERROR(__xludf.DUMMYFUNCTION("""COMPUTED_VALUE"""),"I") -> I | D21: =IFERROR(__xludf.DUMMYFUNCTION("""COMPUTED_VALUE"""),"Shield") -> Shield | E21: =IFERROR(__xludf.DUMMYFUNCTION("""COMPUTED_VALUE"""),1.0) -> 1 | F21: =IFERROR(__xludf.DUMMYFUNCTION("""COMPUTED_VALUE"""),"Starter") -> Starter | G21: =IFERROR(__xludf.DUMMYFUNCTION("""COMPUTED_VALUE"""),1.0) -> 1 | H21: =IFERROR(__xludf.DUMMYFUNCTION("""COMPUTED_VALUE"""),1.0) -> 1 | I21: =IFERROR(__xludf.DUMMYFUNCTION("""COMPUTED_VALUE"""),"---") -> --- | J21: =IFERROR(__xludf.DUMMYFUNCTION("""COMPUTED_VALUE"""),"---") -> --- | K21: =IFERROR(__xludf.DUMMYFUNCTION("""COMPUTED_VALUE"""),"(BLK 4)") -> (BLK 4) | L21: =IFERROR(__xludf.DUMMYFUNCTION("""COMPUTED_VALUE"""),"---") -> --- | M21: =IFERROR(__xludf.DUMMYFUNCTION("""COMPUTED_VALUE"""),"---") -> --- | N21: =IFERROR(__xludf.DUMMYFUNCTION("""COMPUTED_VALUE"""),"---") -> --- | O21: =IFERROR(__xludf.DUMMYFUNCTION("""COMPUTED_VALUE"""),"---") -> --- | P21: =IFERROR(__xludf.DUMMYFUNCTION("""COMPUTED_VALUE"""),"---") -> --- | Q21: =IFERROR(__xludf.DUMMYFUNCTION("""COMPUTED_VALUE"""),"---") -> --- | R21: =IFERROR(__xludf.DUMMYFUNCTION("""COMPUTED_VALUE"""),"---") -> ---
A22: =IFERROR(__xludf.DUMMYFUNCTION("""COMPUTED_VALUE"""),TRUE) -> TRUE | B22: =IFERROR(__xludf.DUMMYFUNCTION("""COMPUTED_VALUE"""),FALSE) -> FALSE | C22: =IFERROR(__xludf.DUMMYFUNCTION("""COMPUTED_VALUE"""),"I") -> I | D22: =IFERROR(__xludf.DUMMYFUNCTION("""COMPUTED_VALUE"""),"Sai") -> Sai | E22: =IFERROR(__xludf.DUMMYFUNCTION("""COMPUTED_VALUE"""),2.0) -> 2 | F22: =IFERROR(__xludf.DUMMYFUNCTION("""COMPUTED_VALUE"""),"Starter") -> Starter | G22: =IFERROR(__xludf.DUMMYFUNCTION("""COMPUTED_VALUE"""),1.0) -> 1 | H22: =IFERROR(__xludf.DUMMYFUNCTION("""COMPUTED_VALUE"""),2.0) -> 2 | I22: =IFERROR(__xludf.DUMMYFUNCTION("""COMPUTED_VALUE"""),"---") -> --- | J22: =IFERROR(__xludf.DUMMYFUNCTION("""COMPUTED_VALUE"""),"---") -> --- | K22: =IFERROR(__xludf.DUMMYFUNCTION("""COMPUTED_VALUE"""),"(ATK 2), or (ATK 4) against monsters with even ATK.") -> (ATK 2), or (ATK 4) against monsters with even ATK. | L22: =IFERROR(__xludf.DUMMYFUNCTION("""COMPUTED_VALUE"""),"(Is enemy ATK even?)") -> (Is enemy ATK even?) | M22: =IFERROR(__xludf.DUMMYFUNCTION("""COMPUTED_VALUE"""),">On Spin >On Enemy ATK Change") -> >On Spin >On Enemy ATK Change | N22: =IFERROR(__xludf.DUMMYFUNCTION("""COMPUTED_VALUE"""),"Its own ATK") -> Its own ATK | O22: =IFERROR(__xludf.DUMMYFUNCTION("""COMPUTED_VALUE"""),">On Spin >On Enemy ATK Change") -> >On Spin >On Enemy ATK Change
A23: =IFERROR(__xludf.DUMMYFUNCTION("""COMPUTED_VALUE"""),TRUE) -> TRUE | B23: =IFERROR(__xludf.DUMMYFUNCTION("""COMPUTED_VALUE"""),FALSE) -> FALSE | C23: =IFERROR(__xludf.DUMMYFUNCTION("""COMPUTED_VALUE"""),"I") -> I | D23: =IFERROR(__xludf.DUMMYFUNCTION("""COMPUTED_VALUE"""),"Medallion") -> Medallion | E23: =IFERROR(__xludf.DUMMYFUNCTION("""COMPUTED_VALUE"""),2.0) -> 2 | F23: =IFERROR(__xludf.DUMMYFUNCTION("""COMPUTED_VALUE"""),"Starter") -> Starter | G23: =IFERROR(__xludf.DUMMYFUNCTION("""COMPUTED_VALUE"""),1.0) -> 1 | H23: =IFERROR(__xludf.DUMMYFUNCTION("""COMPUTED_VALUE"""),1.0) -> 1 | I23: =IFERROR(__xludf.DUMMYFUNCTION("""COMPUTED_VALUE"""),"---") -> --- | J23: =IFERROR(__xludf.DUMMYFUNCTION("""COMPUTED_VALUE"""),"---") -> --- | K23: =IFERROR(__xludf.DUMMYFUNCTION("""COMPUTED_VALUE"""),"(BLK 6-X), where X is your HP.") -> (BLK 6-X), where X is your HP. | L23: =IFERROR(__xludf.DUMMYFUNCTION("""COMPUTED_VALUE"""),"(HP)") -> (HP) | M23: =IFERROR(__xludf.DUMMYFUNCTION("""COMPUTED_VALUE"""),">On Spin >On HP Change") -> >On Spin >On HP Change | N23: =IFERROR(__xludf.DUMMYFUNCTION("""COMPUTED_VALUE"""),"Its own BLK") -> Its own BLK | O23: =IFERROR(__xludf.DUMMYFUNCTION("""COMPUTED_VALUE"""),">On Spin >On HP Change") -> >On Spin >On HP Change | P23: =IFERROR(__xludf.DUMMYFUNCTION("""COMPUTED_VALUE"""),">On HP Change") -> >On HP Change | Q23: =IFERROR(__xludf.DUMMYFUNCTION("""COMPUTED_VALUE"""),"This check occurs each time the player's HP changes.") -> This check occurs each time the player's HP changes.
A24: =IFERROR(__xludf.DUMMYFUNCTION("""COMPUTED_VALUE"""),TRUE) -> TRUE | B24: =IFERROR(__xludf.DUMMYFUNCTION("""COMPUTED_VALUE"""),FALSE) -> FALSE | C24: =IFERROR(__xludf.DUMMYFUNCTION("""COMPUTED_VALUE"""),"I") -> I | D24: =IFERROR(__xludf.DUMMYFUNCTION("""COMPUTED_VALUE"""),"Helmet") -> Helmet | E24: =IFERROR(__xludf.DUMMYFUNCTION("""COMPUTED_VALUE"""),2.0) -> 2 | F24: =IFERROR(__xludf.DUMMYFUNCTION("""COMPUTED_VALUE"""),"Starter") -> Starter | G24: =IFERROR(__xludf.DUMMYFUNCTION("""COMPUTED_VALUE"""),1.0) -> 1 | H24: =IFERROR(__xludf.DUMMYFUNCTION("""COMPUTED_VALUE"""),2.0) -> 2 | I24: =IFERROR(__xludf.DUMMYFUNCTION("""COMPUTED_VALUE"""),"---") -> --- | J24: =IFERROR(__xludf.DUMMYFUNCTION("""COMPUTED_VALUE"""),"---") -> --- | K24: =IFERROR(__xludf.DUMMYFUNCTION("""COMPUTED_VALUE"""),"(BLK X), where X is the lowest HP between you and the enemy.") -> (BLK X), where X is the lowest HP between you and the enemy. | L24: =IFERROR(__xludf.DUMMYFUNCTION("""COMPUTED_VALUE"""),"[Lowest HP]") -> [Lowest HP] | M24: =IFERROR(__xludf.DUMMYFUNCTION("""COMPUTED_VALUE"""),">On Spin >On HP Change >On Enemy HP Change") -> >On Spin >On HP Change >On Enemy HP Change | N24: =IFERROR(__xludf.DUMMYFUNCTION("""COMPUTED_VALUE"""),"Its own BLK") -> Its own BLK | O24: =IFERROR(__xludf.DUMMYFUNCTION("""COMPUTED_VALUE"""),">On Spin >On HP Change >On Enemy HP Change") -> >On Spin >On HP Change >On Enemy HP Change | P24: =IFERROR(__xludf.DUMMYFUNCTION("""COMPUTED_VALUE"""),"[Lowest HP]") -> [Lowest HP] | Q24: =IFERROR(__xludf.DUMMYFUNCTION("""COMPUTED_VALUE"""),"[Lowest HP]: Compares the player's current HP against the enemy's current HP and takes the lower value as X (or the Player's value if tied). This ""check"" occurs every time the enemy's HP changes, or the player's HP changes.") -> [Lowest HP]: Compares the player's current HP against the enemy's current HP and takes the lower value as X (or the Player's value if tied). This "check" occurs every time the enemy's HP changes, or the player's HP changes. | T24: 44675 | U24: Rework: Changed BLK from X = Enemy HP to X = Lowest HP between you and enemy
A25: =IFERROR(__xludf.DUMMYFUNCTION("""COMPUTED_VALUE"""),TRUE) -> TRUE | B25: =IFERROR(__xludf.DUMMYFUNCTION("""COMPUTED_VALUE"""),FALSE) -> FALSE | C25: =IFERROR(__xludf.DUMMYFUNCTION("""COMPUTED_VALUE"""),"I") -> I | D25: =IFERROR(__xludf.DUMMYFUNCTION("""COMPUTED_VALUE"""),"Da Boot") -> Da Boot | E25: =IFERROR(__xludf.DUMMYFUNCTION("""COMPUTED_VALUE"""),2.0) -> 2 | F25: =IFERROR(__xludf.DUMMYFUNCTION("""COMPUTED_VALUE"""),"Starter") -> Starter | G25: =IFERROR(__xludf.DUMMYFUNCTION("""COMPUTED_VALUE"""),1.0) -> 1 | H25: =IFERROR(__xludf.DUMMYFUNCTION("""COMPUTED_VALUE"""),2.0) -> 2 | I25: =IFERROR(__xludf.DUMMYFUNCTION("""COMPUTED_VALUE"""),"---") -> --- | J25: =IFERROR(__xludf.DUMMYFUNCTION("""COMPUTED_VALUE"""),"---") -> --- | K25: =IFERROR(__xludf.DUMMYFUNCTION("""COMPUTED_VALUE"""),"Defeat an enemy with less HP than you.") -> Defeat an enemy with less HP than you. | L25: =IFERROR(__xludf.DUMMYFUNCTION("""COMPUTED_VALUE"""),"(Is enemy HP less?)") -> (Is enemy HP less?) | M25: =IFERROR(__xludf.DUMMYFUNCTION("""COMPUTED_VALUE"""),">On Spin >On HP Change >On Enemy HP Change") -> >On Spin >On HP Change >On Enemy HP Change | N25: =IFERROR(__xludf.DUMMYFUNCTION("""COMPUTED_VALUE"""),"(Usable?)") -> (Usable?) | O25: =IFERROR(__xludf.DUMMYFUNCTION("""COMPUTED_VALUE"""),"Updates whenver (Is enemy HP less?) updates, to match it.") -> Updates whenver (Is enemy HP less?) updates, to match it. | P25: =IFERROR(__xludf.DUMMYFUNCTION("""COMPUTED_VALUE"""),"[Defeat]") -> [Defeat] | Q25: =IFERROR(__xludf.DUMMYFUNCTION("""COMPUTED_VALUE"""),"When used, Resolve Combat immediately, skipping ATK/BLK resolution.") -> When used, Resolve Combat immediately, skipping ATK/BLK resolution. | R25: =IFERROR(__xludf.DUMMYFUNCTION("""COMPUTED_VALUE"""),"---") -> ---
